<!DOCTYPE html>
<html lang="ja">

<head>
  <meta charset="UTF-8">
  <title>12</title>
</head>

<body>
  <p>open console!!</p>
  <script src="https://code.jquery.com/jquery-1.12.4.min.js"></script>
  <script src="https://cdnjs.cloudflare.com/ajax/libs/rxjs/3.1.2/rx.all.min.js"></script>
  <script>
    // 一割の確率でエラーを返す非同期処理
    function myPromise(ms, data) {
      const d = $.Deferred();

      setTimeout(() => {
        if (Math.random() > 0.1) {
          d.resolve(data);
        } else {
          d.reject('Error');
        }
      }, ms);

      return d;
    }

    const item = [{ type: 'A' }, { type: 'B' }, { type: 'C' }, { type: 'D' }, { type: 'F' }];

    // 非同期処理が全てを完了したら値を流す。
    // エラーが発生しても error イベントは発火せず、エラーを含んだ全ての値が流れる。
    Rx.Observable
      .of(item)
      .flatMap(v => Rx.Observable.forkJoin(
        v.map((v, index) => Rx.Observable
          .fromPromise(myPromise(index * 50, v))
          .catch(error => Rx.Observable.of(error)))
      ))
      .subscribe(console.log);
    // 以下のような出力になる。
    // { type: "A" }
    // { type: "B" }
    // { type: "C" }
    // "Error"
    // "Error"
  </script>
</body>

</html>
